<?xml version="1.0"?>
<robot name="my_robot">

    <!-- Base link -->
    <link name="base_link">
        <visual>
            <geometry>
                <box size="0.4 0.3 0.1"/>
            </geometry>
            <origin xyz="0 0 0.05" rpy="0 0 0"/>
            <material name="blue">
                <color rgba="0 0 0.8 1"/>
            </material>
        </visual>
        <collision>
            <geometry>
                <box size="0.4 0.3 0.1"/>
            </geometry>
            <origin xyz="0 0 0.05" rpy="0 0 0"/>
        </collision>
        <inertial>
            <mass value="1.0"/>
            <inertia ixx="0.1" ixy="0.0" ixz="0.0" iyy="0.1" iyz="0.0" izz="0.1"/>
        </inertial>
    </link>

    <!-- Right wheel -->
    <link name="wheel_right_link">
        <visual>
            <geometry>
                <cylinder radius="0.05" length="0.02"/>
            </geometry>
            <origin xyz="0 0 0" rpy="1.57 0 0"/>
            <material name="gray">
                <color rgba="0.5 0.5 0.5 1"/>
            </material>
        </visual>
        <collision>
            <geometry>
                <cylinder radius="0.05" length="0.02"/>
            </geometry>
            <origin xyz="0 0 0" rpy="1.57 0 0"/>
        </collision>
        <inertial>
            <mass value="0.5"/>
            <inertia ixx="0.001" ixy="0.0" ixz="0.0" iyy="0.001" iyz="0.0" izz="0.001"/>
        </inertial>
    </link>

    <!-- Joint: base_link → wheel_right_link -->
    <joint name="wheel_right_joint" type="continuous">
        <parent link="base_link"/>
        <child link="wheel_right_link"/>
        <origin xyz="0 -0.15 0.05" rpy="0 0 0"/>
        <axis xyz="0 1 0"/>
    </joint>

    <!-- Left wheel -->
    <link name="wheel_left_link">
        <visual>
            <geometry>
                <cylinder radius="0.05" length="0.02"/>
            </geometry>
            <origin xyz="0 0 0" rpy="1.57 0 0"/>
            <material name="gray">
                <color rgba="0.5 0.5 0.5 1"/>
            </material>
        </visual>
        <collision>
            <geometry>
                <cylinder radius="0.05" length="0.02"/>
            </geometry>
            <origin xyz="0 0 0" rpy="1.57 0 0"/>
        </collision>
        <inertial>
            <mass value="0.5"/>
            <inertia ixx="0.001" ixy="0.0" ixz="0.0" iyy="0.001" iyz="0.0" izz="0.001"/>
        </inertial>
    </link>

    <!-- Joint: base_link → wheel_left_link -->
    <joint name="wheel_left_joint" type="continuous">
        <parent link="base_link"/>
        <child link="wheel_left_link"/>
        <origin xyz="0 0.15 0.05" rpy="0 0 0"/>
        <axis xyz="0 1 0"/>
    </joint>

</robot>
